Workbook

Sheet Q1_SQL_Summary
A1: analysis_level | B1: entity_count | C1: mean_transaction_count | D1: median_transaction_count | E1: q1_transaction_count | F1: q3_transaction_count | G1: p95_transaction_count | H1: p99_transaction_count | I1: median_entity_amount | J1: q1_entity_amount | K1: q3_entity_amount | L1: p95_entity_amount | M1: p99_entity_amount | N1: frequency_iqr_only_count | O1: frequency_iqr_only_share_pct | P1: frequency_p99_count | Q1: frequency_p99_share_pct | R1: amount_iqr_only_count | S1: amount_iqr_only_share_pct | T1: amount_p99_count | U1: amount_p99_share_pct
A2: Customer | B2: 1219 | C2: 10915.43 | D2: 9832 | E2: 7221 | F2: 13351 | G2: 20792 | H2: 30474 | I2: 31.005 | J2: 18.415 | K2: 44.67 | L2: 71 | M2: 92.4 | N2: 23 | O2: 1.8868 | P2: 13 | Q2: 1.0664 | R2: 7 | S2: 0.5742 | T2: 13 | U2: 1.0664
A3: Card | B3: 4071 | C3: 3268.46 | D3: 2558 | E3: 1418 | F3: 4168 | G3: 8553 | H3: 14364 | I3: 29.74 | J3: 17.15 | K3: 46.015 | L3: 77.39 | M3: 99.18 | N3: 176 | O3: 4.3233 | P3: 41 | Q3: 1.0071 | R3: 50 | S3: 1.2282 | T3: 41 | U3: 1.0071

Sheet Q1_sql_Customer_Detail
A1: client_id | B1: transaction_count | C1: net_transaction_amount | D1: positive_transaction_count | E1: positive_transaction_amount | F1: avg_positive_transaction_amount | G1: median_positive_transaction_amount | H1: avg_median_difference | I1: avg_median_ratio | J1: zero_transaction_count | K1: zero_rate_pct | L1: negative_transaction_count | M1: negative_transaction_amount | N1: negative_rate_pct | O1: error_transaction_count | P1: error_rate_pct | Q1: frequency_flag | R1: amount_level_flag | S1: ratio_flag
A2: 1098 | B2: 48479 | C2: 1460166.8 | D2: 38156 | E2: 2249029.5 | F2: 58.943011 | G2: 58.27 | H2: 0.673011 | I2: 1.01155 | J2: 0 | K2: 0 | L2: 10323 | M2: -788862.73 | N2: 21.293756 | O2: 1125 | P2: 2.320592 | Q2: p99+ | R2: normal | S2: normal
A3: 909 | B3: 43381 | C3: 927496.96 | D3: 33369 | E3: 1698737 | F3: 50.907638 | G3: 37.42 | H3: 13.487638 | I3: 1.360439 | J3: 1 | K3: 0.002305 | L3: 10011 | M3: -771240 | N3: 23.076923 | O3: 477 | P3: 1.09956 | Q3: p99+ | R3: normal | S3: normal
A4: 1963 | B4: 42462 | C4: 1253911.5 | D4: 42137 | E4: 1293900 | F4: 30.706979 | G4: 23.64 | H4: 7.066979 | I4: 1.298942 | J4: 0 | K4: 0 | L4: 325 | M4: -39988.52 | N4: 0.76539 | O4: 654 | P4: 1.540201 | Q4: p99+ | R4: normal | S4: normal
A5: 1776 | B5: 41350 | C5: 1331738.9 | D5: 34491 | E5: 1869408.8 | F5: 54.199902 | G5: 54 | H5: 0.199902 | I5: 1.003702 | J5: 0 | K5: 0 | L5: 6859 | M5: -537669.93 | N5: 16.587666 | O5: 501 | P5: 1.211608 | Q5: p99+ | R5: normal | S5: normal
A6: 114 | B6: 40286 | C6: 942205.88 | D6: 33421 | E6: 1473074.9 | F6: 44.076326 | G6: 39.44 | H6: 4.636326 | I6: 1.117554 | J6: 0 | K6: 0 | L6: 6865 | M6: -530869 | N6: 17.040659 | O6: 796 | P6: 1.975873 | Q6: p99+ | R6: normal | S6: normal
A7: 1888 | B7: 40105 | C7: 1436784.3 | D7: 29148 | E7: 2288609.3 | F7: 78.516855 | G7: 73.55 | H7: 4.966855 | I7: 1.06753 | J7: 0 | K7: 0 | L7: 10957 | M7: -851825 | N7: 27.320783 | O7: 2109 | P7: 5.258696 | Q7: p99+ | R7: normal | S7: normal
A8: 96 | B8: 38617 | C8: 2445773.2 | D8: 31699 | E8: 3002117.1 | F8: 94.706999 | G8: 87.71 | H8: 6.996999 | I8: 1.079774 | J8: 0 | K8: 0 | L8: 6918 | M8: -556343.9 | N8: 17.91439 | O8: 617 | P8: 1.597742 | Q8: p99+ | R8: iqr-outlier | S8: normal
A9: 285 | B9: 32032 | C9: 1615459 | D9: 31682 | E9: 1658959 | F9: 52.362824 | G9: 32.67 | H9: 19.692824 | I9: 1.60278 | J9: 0 | K9: 0 | L9: 350 | M9: -43500 | N9: 1.092657 | O9: 326 | P9: 1.017732 | Q9: p99+ | R9: normal | S9: normal
A10: 1559 | B10: 30979 | C10: 839650.97 | D10: 27619 | E10: 1109981 | F10: 40.189035 | G10: 29.47 | H10: 10.719035 | I10: 1.363727 | J10: 0 | K10: 0 | L10: 3360 | M10: -270330 | N10: 10.846057 | O10: 348 | P10: 1.123342 | Q10: p99+ | R10: normal | S10: normal
A11: 1727 | B11: 30827 | C11: 736981.12 | D11: 24083 | E11: 1262050.1 | F11: 52.404191 | G11: 40.45 | H11: 11.954191 | I11: 1.29553 | J11: 0 | K11: 0 | L11: 6744 | M11: -525069 | N11: 21.876926 | O11: 480 | P11: 1.557077 | Q11: p99+ | R11: normal | S11: normal
A12: 1696 | B12: 30672 | C12: 1181415.1 | D12: 24904 | E12: 1634556.1 | F12: 65.63428 | G12: 57 | H12: 8.63428 | I12: 1.151479 | J12: 0 | K12: 0 | L12: 5768 | M12: -453141 | N12: 18.805425 | O12: 953 | P12: 3.107068 | Q12: p99+ | R12: normal | S12: normal
A13: 1168 | B13: 30520 | C13: 1590822.8 | D13: 23834 | E13: 2116564.8 | F13: 88.804429 | G13: 66 | H13: 22.804429 | I13: 1.345522 | J13: 0 | K13: 0 | L13: 6686 | M13: -525742 | N13: 21.906946 | O13: 357 | P13: 1.169725 | Q13: p99+ | R13: normal | S13: normal
... A1220: 1223 | B1220: 760 | C1220: 111905.55 | D1220: 695 | E1220: 123716.55 | F1220: 178.00942 | G1220: 109.79 | H1220: 68.219424 | I1220: 1.621363 | J1220: 0 | K1220: 0 | L1220: 65 | M1220: -11811 | N1220: 8.552632 | O1220: 9 | P1220: 1.184211 | Q1220: normal | R1220: p99+ | S1220: normal

Sheet Q1_sql_Card_Detail
A1: card_id | B1: client_id | C1: transaction_count | D1: net_transaction_amount | E1: positive_transaction_count | F1: positive_transaction_amount | G1: avg_positive_transaction_amount | H1: median_positive_transaction_amount | I1: avg_median_difference | J1: avg_median_ratio | K1: zero_transaction_count | L1: zero_rate_pct | M1: negative_transaction_count | N1: negative_transaction_amount | O1: negative_rate_pct | P1: error_transaction_count | Q1: error_rate_pct | R1: frequency_flag | S1: amount_level_flag
A2: 4938 | B2: 1776 | C2: 31552 | D2: 1019405.1 | E2: 26268 | F2: 1434634 | G2: 54.615275 | H2: 54.075 | I2: 0.540275 | J2: 1.009991 | K2: 0 | L2: 0 | M2: 5284 | N2: -415228.93 | O2: 16.746957 | P2: 396 | Q2: 1.255071 | R2: p99+ | S2: normal
A3: 2408 | B3: 1696 | C3: 30672 | D3: 1181415.1 | E3: 24904 | F3: 1634556.1 | G3: 65.63428 | H3: 57 | I3: 8.63428 | J3: 1.151479 | K3: 0 | L3: 0 | M3: 5768 | N3: -453141 | O3: 18.805425 | P3: 953 | Q3: 3.107068 | R3: p99+ | S3: normal
A4: 3239 | B4: 1168 | C4: 30520 | D4: 1590822.8 | E4: 23834 | F4: 2116564.8 | G4: 88.804429 | H4: 66 | I4: 22.804429 | J4: 1.345522 | K4: 0 | L4: 0 | M4: 6686 | N4: -525742 | O4: 21.906946 | P4: 357 | Q4: 1.169725 | R4: p99+ | S4: normal
A5: 3233 | B5: 464 | C5: 27619 | D5: 1882901.4 | E5: 27286 | F5: 1926015.4 | G5: 70.586211 | H5: 80 | I5: -9.413789 | J5: 0.882328 | K5: 1 | L5: 0.003621 | M5: 332 | N5: -43114 | O5: 1.202071 | P5: 1196 | Q5: 4.330352 | R5: p99+ | S5: normal
A6: 3801 | B6: 1452 | C6: 25420 | D6: 948538.64 | E6: 18774 | F6: 1475138.6 | G6: 78.573487 | H6: 61.975 | I6: 16.598487 | J6: 1.267826 | K6: 0 | L6: 0 | M6: 6646 | N6: -526600 | O6: 26.144768 | P6: 220 | Q6: 0.86546 | R6: p99+ | S6: normal
A7: 1016 | B7: 1888 | C7: 23424 | D7: 842980.39 | E7: 16990 | F7: 1342737.4 | G7: 79.031041 | H7: 73.79 | I7: 5.241041 | J7: 1.071026 | K7: 0 | L7: 0 | M7: 6434 | N7: -499757 | O7: 27.467555 | P7: 1226 | Q7: 5.233948 | R7: p99+ | S7: normal
A8: 5570 | B8: 557 | C8: 19965 | D8: 625817.01 | E8: 19342 | F8: 688450.01 | G8: 35.593528 | H8: 20.6 | I8: 14.993528 | J8: 1.727841 | K8: 0 | L8: 0 | M8: 623 | N8: -62633 | O8: 3.120461 | P8: 397 | Q8: 1.98848 | R8: p99+ | S8: normal
A9: 5179 | B9: 1098 | C9: 19305 | D9: 685006.28 | E9: 15260 | F9: 997672.28 | G9: 65.378262 | H9: 63.485 | I9: 1.893262 | J9: 1.029822 | K9: 0 | L9: 0 | M9: 4045 | N9: -312666 | O9: 20.953121 | P9: 365 | Q9: 1.890702 | R9: p99+ | S9: normal
A10: 2509 | B10: 1687 | C10: 19203 | D10: 865220.83 | E10: 18860 | F10: 910853.83 | G10: 48.295537 | H10: 24.27 | I10: 24.025537 | J10: 1.989927 | K10: 0 | L10: 0 | M10: 343 | N10: -45633 | O10: 1.786179 | P10: 267 | Q10: 1.390408 | R10: p99+ | S10: normal
A11: 3695 | B11: 96 | C11: 18163 | D11: 814697.31 | E11: 15177 | F11: 1045697.3 | G11: 68.900132 | H11: 67 | I11: 1.900132 | J11: 1.02836 | K11: 0 | L11: 0 | M11: 2986 | N11: -231000 | O11: 16.440015 | P11: 276 | Q11: 1.519573 | R11: p99+ | S11: normal
A12: 1247 | B12: 254 | C12: 18011 | D12: 1013481.4 | E12: 17611 | F12: 1068188.4 | G12: 60.654611 | H12: 52.53 | I12: 8.124611 | J12: 1.154666 | K12: 2 | L12: 0.011104 | M12: 398 | N12: -54707 | O12: 2.209761 | P12: 228 | Q12: 1.265893 | R12: p99+ | S12: normal
A13: 5260 | B13: 1293 | C13: 17670 | D13: 924100.27 | E13: 17202 | F13: 980330.27 | G13: 56.989319 | H13: 33.01 | I13: 23.979319 | J13: 1.726426 | K13: 0 | L13: 0 | M13: 468 | N13: -56230 | O13: 2.648557 | P13: 291 | Q13: 1.646859 | R13: p99+ | S13: normal
... A4072: 6144 | B4072: 737 | C4072: 1 | D4072: 1127.6 | E4072: 1 | F4072: 1127.6 | G4072: 1127.6 | H4072: 1127.6 | I4072: 0 | J4072: 1 | K4072: 0 | L4072: 0 | M4072: 0 | N4072: 0 | O4072: 0 | P4072: 0 | Q4072: 0 | R4072: normal | S4072: p99+

Sheet Q1_Validation
A1: KPI | B1: SQL Value | C1: Excel Recalc | D1: Status
A2: Customer Entity Count | B2: =Q1_SQL_Summary!B2 -> 1219 | C2: =COUNTA(Q1_sql_Customer_Detail!A:A)-1 -> 1219 | D2: =IF(B2=C2,"PASS","FAIL") -> PASS
A3: Card Entity Count | B3: =Q1_SQL_Summary!B3 -> 4071 | C3: =COUNTA(Q1_sql_Card_Detail!A:A)-1 -> 4071 | D3: =IF(B3=C3,"PASS","FAIL") -> PASS
A4: Customer Median Transaction Count | B4: =Q1_SQL_Summary!D2 -> 9832 | C4: =MEDIAN(Q1_sql_Customer_Detail!B:B) -> 9832 | D4: =IF(B4=C4,"PASS","FAIL") -> PASS
A5: Card Median Transaction Count | B5: =Q1_SQL_Summary!D3 -> 2558 | C5: =MEDIAN(Q1_sql_Card_Detail!C:C) -> 2558 | D5: =IF(B5=C5,"PASS","FAIL") -> PASS
A6: Customer Median Positive Transaction Amount | B6: =Q1_SQL_Summary!I2 -> 31.005 | C6: =MEDIAN(Q1_sql_Customer_Detail!G:G) -> 31.005 | D6: =IF(B6=C6,"PASS","FAIL") -> PASS
A7: Card Median Positive Transaction Amount | B7: =Q1_SQL_Summary!I3 -> 29.74 | C7: =MEDIAN(Q1_sql_Card_Detail!H:H) -> 29.74 | D7: =IF(B7=C7,"PASS","FAIL") -> PASS
A8: Customer Frequency IQR-only Share (%) | B8: =Q1_SQL_Summary!O2 -> 1.8868 | C8: =ROUND(COUNTIF(Q1_sql_Customer_Detail!Q:Q,"iqr-outlier")/(COUNTA(Q1_sql_Customer_Detail!A:A)-1)*100,4) -> 1.8868 | D8: =IF(B8=C8,"PASS","FAIL") -> PASS
A9: Card Frequency IQR-only Share (%) | B9: =Q1_SQL_Summary!O3 -> 4.3233 | C9: =ROUND(COUNTIF(Q1_sql_Card_Detail!R:R,"iqr-outlier")/(COUNTA(Q1_sql_Card_Detail!A:A)-1)*100,4) -> 4.3233 | D9: =IF(B9=C9,"PASS","FAIL") -> PASS
A10: Customer Amount IQR-only Share (%) | B10: =Q1_SQL_Summary!S2 -> 0.5742 | C10: =ROUND(COUNTIF(Q1_sql_Customer_Detail!R:R,"iqr-outlier")/(COUNTA(Q1_sql_Customer_Detail!A:A)-1)*100,4) -> 0.5742 | D10: =IF(B10=C10,"PASS","FAIL") -> PASS
A11: Card Amount IQR-only Share (%) | B11: =Q1_SQL_Summary!S3 -> 1.2282 | C11: =ROUND(COUNTIF(Q1_sql_Card_Detail!S:S,"iqr-outlier")/(COUNTA(Q1_sql_Card_Detail!A:A)-1)*100,4) -> 1.2282 | D11: =IF(B11=C11,"PASS","FAIL") -> PASS

Sheet Q2_SQL_Summary
A1: use_chip | B1: transaction_count | C1: transaction_share_pct | D1: positive_transaction_count | E1: avg_positive_transaction_amount | F1: median_positive_transaction_amount | G1: avg_median_difference | H1: avg_median_ratio | I1: zero_transaction_count | J1: zero_rate_pct | K1: negative_transaction_count | L1: negative_rate_pct | M1: error_transaction_count | N1: error_rate_pct
A2: Swipe Transaction | B2: 6967185 | C2: 52.3616 | D2: 6571735 | E2: 49.720855 | F2: 30.88 | G2: 18.840855 | H2: 1.610131 | I2: 6274 | J2: 0.09005 | K2: 389176 | L2: 5.58584 | M2: 103538 | N2: 1.48608
A3: Chip Transaction | B3: 4780818 | C3: 35.93 | D3: 4512267 | E3: 49.069252 | F3: 30.8 | G3: 18.269252 | H3: 1.593158 | I3: 4361 | J3: 0.09122 | K3: 264190 | L3: 5.52604 | M3: 72294 | N3: 1.51217
A4: Online Transaction | B4: 1557912 | C4: 11.7084 | D4: 1551225 | E4: 58.784971 | F4: 35.3 | G4: 23.484971 | H4: 1.665297 | I4: 4 | J4: 0.00026 | K4: 6683 | L4: 0.42897 | M4: 35561 | N4: 2.28261

Sheet Q2_sql_validation_base
A1: transaction_month | B1: use_chip | C1: transaction_count | D1: positive_transaction_count | E1: positive_transaction_amount | F1: zero_transaction_count | G1: negative_transaction_count | H1: error_transaction_count
A2: 40179 | B2: Online Transaction | C2: 11143 | D2: 11078 | E2: 658937.72 | F2: 0 | G2: 65 | H2: 255
A3: 40179 | B3: Swipe Transaction | C3: 90066 | D3: 84786 | E3: 4245510.6 | F3: 83 | G3: 5197 | H3: 1320
A4: 40210 | B4: Online Transaction | C4: 10354 | D4: 10281 | E4: 631414.67 | F4: 0 | G4: 73 | H4: 220
A5: 40210 | B5: Swipe Transaction | C5: 83116 | D5: 78271 | E5: 3963856.6 | F5: 78 | G5: 4767 | H5: 1222
A6: 40238 | B6: Online Transaction | C6: 11205 | D6: 11125 | E6: 697393.78 | F6: 0 | G6: 80 | H6: 251
A7: 40238 | B7: Swipe Transaction | C7: 92140 | D7: 86822 | E7: 4371963.5 | F7: 80 | G7: 5238 | H7: 1333
A8: 40269 | B8: Online Transaction | C8: 10808 | D8: 10709 | E8: 671756.55 | F8: 1 | G8: 98 | H8: 220
A9: 40269 | B9: Swipe Transaction | C9: 89361 | D9: 84120 | E9: 4273048.3 | F9: 86 | G9: 5155 | H9: 1260
A10: 40299 | B10: Online Transaction | C10: 11639 | D10: 11555 | E10: 718350.13 | F10: 0 | G10: 84 | H10: 264
A11: 40299 | B11: Swipe Transaction | C11: 93134 | D11: 87759 | E11: 4445973.1 | F11: 97 | G11: 5278 | H11: 1356
A12: 40330 | B12: Online Transaction | C12: 11152 | D12: 11049 | E12: 683038.24 | F12: 0 | G12: 103 | H12: 272
A13: 40330 | B13: Swipe Transaction | C13: 91525 | D13: 86092 | E13: 4405417.5 | F13: 79 | G13: 5354 | H13: 1399
... A295: 43739 | B295: Swipe Transaction | C295: 20097 | D295: 18968 | E295: 934378.67 | F295: 14 | G295: 1115 | H295: 303

Sheet Q2_Validation
A1: Payment Method | B1: KPI | C1: SQL Value | D1: Excel Recalc | E1: Status
A2: Swipe Transaction | B2: Transaction Count | C2: =Q2_SQL_Summary!B2 -> 6967185 | D2: =SUMIF(Q2_sql_validation_base!B:B,A2,Q2_sql_validation_base!C:C) -> 6967185 | E2: =IF(C2=D2,"PASS","FAIL") -> PASS
A3: Chip Transaction | B3: Transaction Count | C3: =Q2_SQL_Summary!B3 -> 4780818 | D3: =SUMIF(Q2_sql_validation_base!B:B,A3,Q2_sql_validation_base!C:C) -> 4780818 | E3: =IF(C3=D3,"PASS","FAIL") -> PASS
A4: Online Transaction | B4: Transaction Count | C4: =Q2_SQL_Summary!B4 -> 1557912 | D4: =SUMIF(Q2_sql_validation_base!B:B,A4,Q2_sql_validation_base!C:C) -> 1557912 | E4: =IF(C4=D4,"PASS","FAIL") -> PASS
A6: Swipe Transaction | B6: Transaction Share (%) | C6: =Q2_SQL_Summary!C2 -> 52.3616 | D6: =ROUND(D2/SUM($D$2:$D$4)*100,4) -> 52.3616 | E6: =IF(C6=D6,"PASS","FAIL") -> PASS
A7: Chip Transaction | B7: Transaction Share (%) | C7: =Q2_SQL_Summary!C3 -> 35.93 | D7: =ROUND(D3/SUM($D$2:$D$4)*100,4) -> 35.93 | E7: =IF(C7=D7,"PASS","FAIL") -> PASS
A8: Online Transaction | B8: Transaction Share (%) | C8: =Q2_SQL_Summary!C4 -> 11.7084 | D8: =ROUND(D4/SUM($D$2:$D$4)*100,4) -> 11.7084 | E8: =IF(C8=D8,"PASS","FAIL") -> PASS
A10: Swipe Transaction | B10: Avg Positive Transaction Amount | C10: =Q2_SQL_Summary!E2 -> 49.720855 | D10: =ROUND(SUMIF(Q2_sql_validation_base!B:B,A10,Q2_sql_validation_base!E:E)/SUMIF(Q2_sql_validation_base!B:B,A10,Q2_sql_validation_base!D:D),6) -> 49.720855 | E10: =IF(C10=D10,"PASS","FAIL") -> PASS
A11: Chip Transaction | B11: Avg Positive Transaction Amount | C11: =Q2_SQL_Summary!E3 -> 49.069252 | D11: =ROUND(SUMIF(Q2_sql_validation_base!B:B,A11,Q2_sql_validation_base!E:E)/SUMIF(Q2_sql_validation_base!B:B,A11,Q2_sql_validation_base!D:D),6) -> 49.069252 | E11: =IF(C11=D11,"PASS","FAIL") -> PASS
A12: Online Transaction | B12: Avg Positive Transaction Amount | C12: =Q2_SQL_Summary!E4 -> 58.784971 | D12: =ROUND(SUMIF(Q2_sql_validation_base!B:B,A12,Q2_sql_validation_base!E:E)/SUMIF(Q2_sql_validation_base!B:B,A12,Q2_sql_validation_base!D:D),6) -> 58.784971 | E12: =IF(C12=D12,"PASS","FAIL") -> PASS
A14: Swipe Transaction | B14: Zero Rate (%) | C14: =Q2_SQL_Summary!J2 -> 0.09005 | D14: =ROUND(SUMIF(Q2_sql_validation_base!B:B,A14,Q2_sql_validation_base!F:F)/SUMIF(Q2_sql_validation_base!B:B,A14,Q2_sql_validation_base!C:C)*100,5) -> 0.09005 | E14: =IF(C14=D14,"PASS","FAIL") -> PASS
A15: Chip Transaction | B15: Zero Rate (%) | C15: =Q2_SQL_Summary!J3 -> 0.09122 | D15: =ROUND(SUMIF(Q2_sql_validation_base!B:B,A15,Q2_sql_validation_base!F:F)/SUMIF(Q2_sql_validation_base!B:B,A15,Q2_sql_validation_base!C:C)*100,5) -> 0.09122 | E15: =IF(C15=D15,"PASS","FAIL") -> PASS
A16: Online Transaction | B16: Zero Rate (%) | C16: =Q2_SQL_Summary!J4 -> 0.00026 | D16: =ROUND(SUMIF(Q2_sql_validation_base!B:B,A16,Q2_sql_validation_base!F:F)/SUMIF(Q2_sql_validation_base!B:B,A16,Q2_sql_validation_base!C:C)*100,5) -> 0.00026 | E16: =IF(C16=D16,"PASS","FAIL") -> PASS
A18: Swipe Transaction | B18: Negative Rate (%) | C18: =Q2_SQL_Summary!L2 -> 5.58584 | D18: =ROUND(SUMIF(Q2_sql_validation_base!B:B,A18,Q2_sql_validation_base!G:G)/SUMIF(Q2_sql_validation_base!B:B,A18,Q2_sql_validation_base!C:C)*100,5) -> 5.58584 | E18: =IF(C18=D18,"PASS","FAIL") -> PASS
A19: Chip Transaction | B19: Negative Rate (%) | C19: =Q2_SQL_Summary!L3 -> 5.52604 | D19: =ROUND(SUMIF(Q2_sql_validation_base!B:B,A19,Q2_sql_validation_base!G:G)/SUMIF(Q2_sql_validation_base!B:B,A19,Q2_sql_validation_base!C:C)*100,5) -> 5.52604 | E19: =IF(C19=D19,"PASS","FAIL") -> PASS
A20: Online Transaction | B20: Negative Rate (%) | C20: =Q2_SQL_Summary!L4 -> 0.42897 | D20: =ROUND(SUMIF(Q2_sql_validation_base!B:B,A20,Q2_sql_validation_base!G:G)/SUMIF(Q2_sql_validation_base!B:B,A20,Q2_sql_validation_base!C:C)*100,5) -> 0.42897 | E20: =IF(C20=D20,"PASS","FAIL") -> PASS
A22: Swipe Transaction | B22: Error Rate (%) | C22: =Q2_SQL_Summary!N2 -> 1.48608 | D22: =ROUND(SUMIF(Q2_sql_validation_base!B:B,A22,Q2_sql_validation_base!H:H)/SUMIF(Q2_sql_validation_base!B:B,A22,Q2_sql_validation_base!C:C)*100,5) -> 1.48608 | E22: =IF(C22=D22,"PASS","FAIL") -> PASS
A23: Chip Transaction | B23: Error Rate (%) | C23: =Q2_SQL_Summary!N3 -> 1.51217 | D23: =ROUND(SUMIF(Q2_sql_validation_base!B:B,A23,Q2_sql_validation_base!H:H)/SUMIF(Q2_sql_validation_base!B:B,A23,Q2_sql_validation_base!C:C)*100,5) -> 1.51217 | E23: =IF(C23=D23,"PASS","FAIL") -> PASS
A24: Online Transaction | B24: Error Rate (%) | C24: =Q2_SQL_Summary!N4 -> 2.28261 | D24: =ROUND(SUMIF(Q2_sql_validation_base!B:B,A24,Q2_sql_validation_base!H:H)/SUMIF(Q2_sql_validation_base!B:B,A24,Q2_sql_validation_base!C:C)*100,5) -> 2.28261 | E24: =IF(C24=D24,"PASS","FAIL") -> PASS

Sheet Q3_SQL_Methodology
A1: baseline_error_rate_pct | B1: confidence_level_pct | C1: z_score | D1: margin_of_error_pct | E1: minimum_transaction_count | F1: eligible_q1_error_rate_pct | G1: eligible_median_error_rate_pct | H1: high_error_threshold_pct | I1: eligible_iqr_error_rate_pct | J1: outlier_upper_bound_error_rate_pct
A2: 1.589 | B2: 95 | C2: 1.96 | D2: 1 | E2: 601 | F2: 1.0994 | G2: 1.6067 | H2: 2.1109 | I2: 1.0115 | J2: 3.6282

Sheet Q3_Validation_Base
A1: mcc | B1: hour_of_day | C1: use_chip | D1: transaction_count | E1: error_transaction_count | F1: Excel Error Rate (%) | G1: SQL Final Error Rate (%) | H1: Rate Status | I1: Excel Eligible Flag | J1: Excel Eligible Error Rate (%) | K1: error_level | L1: high_error_segment_count_by_mcc | M1: final_flag
A2: 1711 | B2: 0 | C2: Chip Transaction | D2: 2 | E2: 0 | F2: =100*E2/D2 -> 0 | G2: =IF(COUNTIFS(Q3_SQL_Error_Concentration!$A:$A,A2,Q3_SQL_Error_Concentration!$E:$E,B2,Q3_SQL_Error_Concentration!$F:$F,C2)=0,"",SUMIFS(Q3_SQL_Error_Concentration!$I:$I,Q3_SQL_Error_Concentration!$A:$A,A2,Q3_SQL_Error_Concentration!$E:$E,B2,Q3_SQL_Error_Concentration!$F:$F,C2)) | H2: =IF(G2="","",IF(ABS(F2-G2)<=0.0002,"PASS","FAIL")) | I2: =IF(D2>=Q3_Validation!$C$2,1,0) -> 0 | J2: =IF(I2=1,F2,"") | K2: =IF(D2<601,"excluded",IF(J2>3.628192,"outlier",IF(J2>=2.11093,"high-error","normal"))) -> excluded | L2: =COUNTIFS(A:A,A2,K:K,"high-error")+COUNTIFS(A:A,A2,K:K,"outlier") -> 0 | M2: =IF(AND(L2>=2,OR(K2="high-error",K2="outlier")),1,0) -> 0
A3: 1711 | B3: 0 | C3: Swipe Transaction | D3: 3 | E3: 0 | F3: =100*E3/D3 -> 0 | G3: =IF(COUNTIFS(Q3_SQL_Error_Concentration!$A:$A,A3,Q3_SQL_Error_Concentration!$E:$E,B3,Q3_SQL_Error_Concentration!$F:$F,C3)=0,"",SUMIFS(Q3_SQL_Error_Concentration!$I:$I,Q3_SQL_Error_Concentration!$A:$A,A3,Q3_SQL_Error_Concentration!$E:$E,B3,Q3_SQL_Error_Concentration!$F:$F,C3)) | H3: =IF(G3="","",IF(ABS(F3-G3)<=0.0002,"PASS","FAIL")) | I3: =IF(D3>=Q3_Validation!$C$2,1,0) -> 0 | J3: =IF(I3=1,F3,"") | K3: =IF(D3<601,"excluded",IF(J3>3.628192,"outlier",IF(J3>=2.11093,"high-error","normal"))) -> excluded | L3: =COUNTIFS(A:A,A3,K:K,"high-error")+COUNTIFS(A:A,A3,K:K,"outlier") -> 0 | M3: =IF(AND(L3>=2,OR(K3="high-error",K3="outlier")),1,0) -> 0
A4: 1711 | B4: 1 | C4: Chip Transaction | D4: 1 | E4: 0 | F4: =100*E4/D4 -> 0 | G4: =IF(COUNTIFS(Q3_SQL_Error_Concentration!$A:$A,A4,Q3_SQL_Error_Concentration!$E:$E,B4,Q3_SQL_Error_Concentration!$F:$F,C4)=0,"",SUMIFS(Q3_SQL_Error_Concentration!$I:$I,Q3_SQL_Error_Concentration!$A:$A,A4,Q3_SQL_Error_Concentration!$E:$E,B4,Q3_SQL_Error_Concentration!$F:$F,C4)) | H4: =IF(G4="","",IF(ABS(F4-G4)<=0.0002,"PASS","FAIL")) | I4: =IF(D4>=Q3_Validation!$C$2,1,0) -> 0 | J4: =IF(I4=1,F4,"") | K4: =IF(D4<601,"excluded",IF(J4>3.628192,"outlier",IF(J4>=2.11093,"high-error","normal"))) -> excluded | L4: =COUNTIFS(A:A,A4,K:K,"high-error")+COUNTIFS(A:A,A4,K:K,"outlier") -> 0 | M4: =IF(AND(L4>=2,OR(K4="high-error",K4="outlier")),1,0) -> 0
A5: 1711 | B5: 2 | C5: Chip Transaction | D5: 6 | E5: 0 | F5: =100*E5/D5 -> 0 | G5: =IF(COUNTIFS(Q3_SQL_Error_Concentration!$A:$A,A5,Q3_SQL_Error_Concentration!$E:$E,B5,Q3_SQL_Error_Concentration!$F:$F,C5)=0,"",SUMIFS(Q3_SQL_Error_Concentration!$I:$I,Q3_SQL_Error_Concentration!$A:$A,A5,Q3_SQL_Error_Concentration!$E:$E,B5,Q3_SQL_Error_Concentration!$F:$F,C5)) | H5: =IF(G5="","",IF(ABS(F5-G5)<=0.0002,"PASS","FAIL")) | I5: =IF(D5>=Q3_Validation!$C$2,1,0) -> 0 | J5: =IF(I5=1,F5,"") | K5: =IF(D5<601,"excluded",IF(J5>3.628192,"outlier",IF(J5>=2.11093,"high-error","normal"))) -> excluded | L5: =COUNTIFS(A:A,A5,K:K,"high-error")+COUNTIFS(A:A,A5,K:K,"outlier") -> 0 | M5: =IF(AND(L5>=2,OR(K5="high-error",K5="outlier")),1,0) -> 0
A6: 1711 | B6: 2 | C6: Swipe Transaction | D6: 12 | E6: 0 | F6: =100*E6/D6 -> 0 | G6: =IF(COUNTIFS(Q3_SQL_Error_Concentration!$A:$A,A6,Q3_SQL_Error_Concentration!$E:$E,B6,Q3_SQL_Error_Concentration!$F:$F,C6)=0,"",SUMIFS(Q3_SQL_Error_Concentration!$I:$I,Q3_SQL_Error_Concentration!$A:$A,A6,Q3_SQL_Error_Concentration!$E:$E,B6,Q3_SQL_Error_Concentration!$F:$F,C6)) | H6: =IF(G6="","",IF(ABS(F6-G6)<=0.0002,"PASS","FAIL")) | I6: =IF(D6>=Q3_Validation!$C$2,1,0) -> 0 | J6: =IF(I6=1,F6,"") | K6: =IF(D6<601,"excluded",IF(J6>3.628192,"outlier",IF(J6>=2.11093,"high-error","normal"))) -> excluded | L6: =COUNTIFS(A:A,A6,K:K,"high-error")+COUNTIFS(A:A,A6,K:K,"outlier") -> 0 | M6: =IF(AND(L6>=2,OR(K6="high-error",K6="outlier")),1,0) -> 0
A7: 1711 | B7: 3 | C7: Chip Transaction | D7: 2 | E7: 0 | F7: =100*E7/D7 -> 0 | G7: =IF(COUNTIFS(Q3_SQL_Error_Concentration!$A:$A,A7,Q3_SQL_Error_Concentration!$E:$E,B7,Q3_SQL_Error_Concentration!$F:$F,C7)=0,"",SUMIFS(Q3_SQL_Error_Concentration!$I:$I,Q3_SQL_Error_Concentration!$A:$A,A7,Q3_SQL_Error_Concentration!$E:$E,B7,Q3_SQL_Error_Concentration!$F:$F,C7)) | H7: =IF(G7="","",IF(ABS(F7-G7)<=0.0002,"PASS","FAIL")) | I7: =IF(D7>=Q3_Validation!$C$2,1,0) -> 0 | J7: =IF(I7=1,F7,"") | K7: =IF(D7<601,"excluded",IF(J7>3.628192,"outlier",IF(J7>=2.11093,"high-error","normal"))) -> excluded | L7: =COUNTIFS(A:A,A7,K:K,"high-error")+COUNTIFS(A:A,A7,K:K,"outlier") -> 0 | M7: =IF(AND(L7>=2,OR(K7="high-error",K7="outlier")),1,0) -> 0
A8: 1711 | B8: 3 | C8: Swipe Transaction | D8: 6 | E8: 0 | F8: =100*E8/D8 -> 0 | G8: =IF(COUNTIFS(Q3_SQL_Error_Concentration!$A:$A,A8,Q3_SQL_Error_Concentration!$E:$E,B8,Q3_SQL_Error_Concentration!$F:$F,C8)=0,"",SUMIFS(Q3_SQL_Error_Concentration!$I:$I,Q3_SQL_Error_Concentration!$A:$A,A8,Q3_SQL_Error_Concentration!$E:$E,B8,Q3_SQL_Error_Concentration!$F:$F,C8)) | H8: =IF(G8="","",IF(ABS(F8-G8)<=0.0002,"PASS","FAIL")) | I8: =IF(D8>=Q3_Validation!$C$2,1,0) -> 0 | J8: =IF(I8=1,F8,"") | K8: =IF(D8<601,"excluded",IF(J8>3.628192,"outlier",IF(J8>=2.11093,"high-error","normal"))) -> excluded | L8: =COUNTIFS(A:A,A8,K:K,"high-error")+COUNTIFS(A:A,A8,K:K,"outlier") -> 0 | M8: =IF(AND(L8>=2,OR(K8="high-error",K8="outlier")),1,0) -> 0
A9: 1711 | B9: 4 | C9: Chip Transaction | D9: 3 | E9: 0 | F9: =100*E9/D9 -> 0 | G9: =IF(COUNTIFS(Q3_SQL_Error_Concentration!$A:$A,A9,Q3_SQL_Error_Concentration!$E:$E,B9,Q3_SQL_Error_Concentration!$F:$F,C9)=0,"",SUMIFS(Q3_SQL_Error_Concentration!$I:$I,Q3_SQL_Error_Concentration!$A:$A,A9,Q3_SQL_Error_Concentration!$E:$E,B9,Q3_SQL_Error_Concentration!$F:$F,C9)) | H9: =IF(G9="","",IF(ABS(F9-G9)<=0.0002,"PASS","FAIL")) | I9: =IF(D9>=Q3_Validation!$C$2,1,0) -> 0 | J9: =IF(I9=1,F9,"") | K9: =IF(D9<601,"excluded",IF(J9>3.628192,"outlier",IF(J9>=2.11093,"high-error","normal"))) -> excluded | L9: =COUNTIFS(A:A,A9,K:K,"high-error")+COUNTIFS(A:A,A9,K:K,"outlier") -> 0 | M9: =IF(AND(L9>=2,OR(K9="high-error",K9="outlier")),1,0) -> 0
A10: 1711 | B10: 4 | C10: Swipe Transaction | D10: 6 | E10: 0 | F10: =100*E10/D10 -> 0 | G10: =IF(COUNTIFS(Q3_SQL_Error_Concentration!$A:$A,A10,Q3_SQL_Error_Concentration!$E:$E,B10,Q3_SQL_Error_Concentration!$F:$F,C10)=0,"",SUMIFS(Q3_SQL_Error_Concentration!$I:$I,Q3_SQL_Error_Concentration!$A:$A,A10,Q3_SQL_Error_Concentration!$E:$E,B10,Q3_SQL_Error_Concentration!$F:$F,C10)) | H10: =IF(G10="","",IF(ABS(F10-G10)<=0.0002,"PASS","FAIL")) | I10: =IF(D10>=Q3_Validation!$C$2,1,0) -> 0 | J10: =IF(I10=1,F10,"") | K10: =IF(D10<601,"excluded",IF(J10>3.628192,"outlier",IF(J10>=2.11093,"high-error","normal"))) -> excluded | L10: =COUNTIFS(A:A,A10,K:K,"high-error")+COUNTIFS(A:A,A10,K:K,"outlier") -> 0 | M10: =IF(AND(L10>=2,OR(K10="high-error",K10="outlier")),1,0) -> 0
A11: 1711 | B11: 5 | C11: Chip Transaction | D11: 3 | E11: 0 | F11: =100*E11/D11 -> 0 | G11: =IF(COUNTIFS(Q3_SQL_Error_Concentration!$A:$A,A11,Q3_SQL_Error_Concentration!$E:$E,B11,Q3_SQL_Error_Concentration!$F:$F,C11)=0,"",SUMIFS(Q3_SQL_Error_Concentration!$I:$I,Q3_SQL_Error_Concentration!$A:$A,A11,Q3_SQL_Error_Concentration!$E:$E,B11,Q3_SQL_Error_Concentration!$F:$F,C11)) | H11: =IF(G11="","",IF(ABS(F11-G11)<=0.0002,"PASS","FAIL")) | I11: =IF(D11>=Q3_Validation!$C$2,1,0) -> 0 | J11: =IF(I11=1,F11,"") | K11: =IF(D11<601,"excluded",IF(J11>3.628192,"outlier",IF(J11>=2.11093,"high-error","normal"))) -> excluded | L11: =COUNTIFS(A:A,A11,K:K,"high-error")+COUNTIFS(A:A,A11,K:K,"outlier") -> 0 | M11: =IF(AND(L11>=2,OR(K11="high-error",K11="outlier")),1,0) -> 0
A12: 1711 | B12: 5 | C12: Swipe Transaction | D12: 6 | E12: 0 | F12: =100*E12/D12 -> 0 | G12: =IF(COUNTIFS(Q3_SQL_Error_Concentration!$A:$A,A12,Q3_SQL_Error_Concentration!$E:$E,B12,Q3_SQL_Error_Concentration!$F:$F,C12)=0,"",SUMIFS(Q3_SQL_Error_Concentration!$I:$I,Q3_SQL_Error_Concentration!$A:$A,A12,Q3_SQL_Error_Concentration!$E:$E,B12,Q3_SQL_Error_Concentration!$F:$F,C12)) | H12: =IF(G12="","",IF(ABS(F12-G12)<=0.0002,"PASS","FAIL")) | I12: =IF(D12>=Q3_Validation!$C$2,1,0) -> 0 | J12: =IF(I12=1,F12,"") | K12: =IF(D12<601,"excluded",IF(J12>3.628192,"outlier",IF(J12>=2.11093,"high-error","normal"))) -> excluded | L12: =COUNTIFS(A:A,A12,K:K,"high-error")+COUNTIFS(A:A,A12,K:K,"outlier") -> 0 | M12: =IF(AND(L12>=2,OR(K12="high-error",K12="outlier")),1,0) -> 0
A13: 1711 | B13: 6 | C13: Chip Transaction | D13: 94 | E13: 2 | F13: =100*E13/D13 -> 2.1276596 | G13: =IF(COUNTIFS(Q3_SQL_Error_Concentration!$A:$A,A13,Q3_SQL_Error_Concentration!$E:$E,B13,Q3_SQL_Error_Concentration!$F:$F,C13)=0,"",SUMIFS(Q3_SQL_Error_Concentration!$I:$I,Q3_SQL_Error_Concentration!$A:$A,A13,Q3_SQL_Error_Concentration!$E:$E,B13,Q3_SQL_Error_Concentration!$F:$F,C13)) | H13: =IF(G13="","",IF(ABS(F13-G13)<=0.0002,"PASS","FAIL")) | I13: =IF(D13>=Q3_Validation!$C$2,1,0) -> 0 | J13: =IF(I13=1,F13,"") | K13: =IF(D13<601,"excluded",IF(J13>3.628192,"outlier",IF(J13>=2.11093,"high-error","normal"))) -> excluded | L13: =COUNTIFS(A:A,A13,K:K,"high-error")+COUNTIFS(A:A,A13,K:K,"outlier") -> 0 | M13: =IF(AND(L13>=2,OR(K13="high-error",K13="outlier")),1,0) -> 0
... A6050: 9402 | B6050: 23 | C6050: Swipe Transaction | D6050: 1 | E6050: 0 | F6050: =100*E6050/D6050 -> 0 | G6050: =IF(COUNTIFS(Q3_SQL_Error_Concentration!$A:$A,A6050,Q3_SQL_Error_Concentration!$E:$E,B6050,Q3_SQL_Error_Concentration!$F:$F,C6050)=0,"",SUMIFS(Q3_SQL_Error_Concentration!$I:$I,Q3_SQL_Error_Concentration!$A:$A,A6050,Q3_SQL_Error_Concentration!$E:$E,B6050,Q3_SQL_Error_Concentration!$F:$F,C6050)) | H6050: =IF(G6050="","",IF(ABS(F6050-G6050)<=0.0002,"PASS","FAIL")) | I6050: =IF(D6050>=Q3_Validation!$C$2,1,0) -> 0 | J6050: =IF(I6050=1,F6050,"") | K6050: =IF(D6050<601,"excluded",IF(J6050>3.628192,"outlier",IF(J6050>=2.11093,"high-error","normal"))) -> excluded | L6050: =COUNTIFS(A:A,A6050,K:K,"high-error")+COUNTIFS(A:A,A6050,K:K,"outlier") -> 0 | M6050: =IF(AND(L6050>=2,OR(K6050="high-error",K6050="outlier")),1,0) -> 0

Sheet Q3_SQL_Error_Concentration
A1: mcc | B1: high_error_segment_count | C1: outlier_segment_count | D1: mcc_avg_eligible_segment_error_rate_pct | E1: hour_of_day | F1: use_chip | G1: transaction_count | H1: error_transaction_count | I1: error_rate_pct | J1: error_level | K1: Excel Recalc Error Level | L1: Classification Match
A2: 4900 | B2: 50 | C2: 2 | D2: 2.502 | E2: 19 | F2: Online Transaction | G2: 3187 | H2: 126 | I2: 3.9536 | J2: outlier | K2: =IF(I2>3.628193,"outlier",IF(I2>=2.11093,"high-error","normal")) -> outlier | L2: =IF(J2=K2,"PASS","FAIL") -> PASS
A3: 4900 | B3: 50 | C3: 2 | D3: 2.502 | E3: 7 | F3: Online Transaction | G3: 3292 | H3: 123 | I3: 3.7363 | J3: outlier | K3: =IF(I3>3.628193,"outlier",IF(I3>=2.11093,"high-error","normal")) -> outlier | L3: =IF(J3=K3,"PASS","FAIL") -> PASS
A4: 4900 | B4: 50 | C4: 2 | D4: 2.502 | E4: 3 | F4: Online Transaction | G4: 2071 | H4: 73 | I4: 3.5249 | J4: high-error | K4: =IF(I4>3.628193,"outlier",IF(I4>=2.11093,"high-error","normal")) -> high-error | L4: =IF(J4=K4,"PASS","FAIL") -> PASS
A5: 4900 | B5: 50 | C5: 2 | D5: 2.502 | E5: 2 | F5: Online Transaction | G5: 2106 | H5: 74 | I5: 3.5138 | J5: high-error | K5: =IF(I5>3.628193,"outlier",IF(I5>=2.11093,"high-error","normal")) -> high-error | L5: =IF(J5=K5,"PASS","FAIL") -> PASS
A6: 4900 | B6: 50 | C6: 2 | D6: 2.502 | E6: 16 | F6: Online Transaction | G6: 4859 | H6: 168 | I6: 3.4575 | J6: high-error | K6: =IF(I6>3.628193,"outlier",IF(I6>=2.11093,"high-error","normal")) -> high-error | L6: =IF(J6=K6,"PASS","FAIL") -> PASS
A7: 4900 | B7: 50 | C7: 2 | D7: 2.502 | E7: 1 | F7: Online Transaction | G7: 2240 | H7: 75 | I7: 3.3482 | J7: high-error | K7: =IF(I7>3.628193,"outlier",IF(I7>=2.11093,"high-error","normal")) -> high-error | L7: =IF(J7=K7,"PASS","FAIL") -> PASS
A8: 4900 | B8: 50 | C8: 2 | D8: 2.502 | E8: 5 | F8: Online Transaction | G8: 2608 | H8: 87 | I8: 3.3359 | J8: high-error | K8: =IF(I8>3.628193,"outlier",IF(I8>=2.11093,"high-error","normal")) -> high-error | L8: =IF(J8=K8,"PASS","FAIL") -> PASS
A9: 4900 | B9: 50 | C9: 2 | D9: 2.502 | E9: 18 | F9: Online Transaction | G9: 2822 | H9: 91 | I9: 3.2247 | J9: high-error | K9: =IF(I9>3.628193,"outlier",IF(I9>=2.11093,"high-error","normal")) -> high-error | L9: =IF(J9=K9,"PASS","FAIL") -> PASS
A10: 4900 | B10: 50 | C10: 2 | D10: 2.502 | E10: 4 | F10: Online Transaction | G10: 2374 | H10: 76 | I10: 3.2014 | J10: high-error | K10: =IF(I10>3.628193,"outlier",IF(I10>=2.11093,"high-error","normal")) -> high-error | L10: =IF(J10=K10,"PASS","FAIL") -> PASS
A11: 4900 | B11: 50 | C11: 2 | D11: 2.502 | E11: 17 | F11: Online Transaction | G11: 3305 | H11: 104 | I11: 3.1468 | J11: high-error | K11: =IF(I11>3.628193,"outlier",IF(I11>=2.11093,"high-error","normal")) -> high-error | L11: =IF(J11=K11,"PASS","FAIL") -> PASS
A12: 4900 | B12: 50 | C12: 2 | D12: 2.502 | E12: 14 | F12: Online Transaction | G12: 4835 | H12: 152 | I12: 3.1437 | J12: high-error | K12: =IF(I12>3.628193,"outlier",IF(I12>=2.11093,"high-error","normal")) -> high-error | L12: =IF(J12=K12,"PASS","FAIL") -> PASS
A13: 4900 | B13: 50 | C13: 2 | D13: 2.502 | E13: 12 | F13: Online Transaction | G13: 5020 | H13: 156 | I13: 3.1076 | J13: high-error | K13: =IF(I13>3.628193,"outlier",IF(I13>=2.11093,"high-error","normal")) -> high-error | L13: =IF(J13=K13,"PASS","FAIL") -> PASS
... A392: 8021 | B392: 2 | C392: 0 | D392: 1.6953 | E392: 14 | F392: Swipe Transaction | G392: 1748 | H392: 42 | I392: 2.4028 | J392: high-error | K392: =IF(I392>3.628193,"outlier",IF(I392>=2.11093,"high-error","normal")) -> high-error | L392: =IF(J392=K392,"PASS","FAIL") -> PASS

Sheet Q3_Validation
A1: KPI | B1: SQL Value | C1: Excel Recalc | D1: Status | E1: Q3-3 High-error / Outlier Classification Helper
A2: Minimum Eligible Transaction Count | B2: =Q3_SQL_Methodology!E2 -> 601 | C2: =ROUNDUP((1.96^2*(G3/100)*(1-G3/100))/((1/100)^2),0) -> 601 | D2: =IF(B2=C2,"PASS","FAIL") -> PASS | G2: Excel
F3: Baseline Error Rate (%) | G3: =ROUND(SUM(Q3_Validation_Base!E:E)/SUM(Q3_Validation_Base!D:D)*100,3) -> 1.589
A4: Final Flagged Segment Error Rate (%) | B4: =SUM(Q3_SQL_Error_Concentration!H:H)/SUM(Q3_SQL_Error_Concentration!G:G)*100 -> 2.8255568 | C4: =SUMIFS(Q3_Validation_Base!E:E,Q3_Validation_Base!M:M,1)/SUMIFS(Q3_Validation_Base!D:D,Q3_Validation_Base!M:M,1)*100 -> 2.8255568 | D4: =IF(B4=C4,"PASS","FAIL") -> PASS | F4: Raw Q1 Error Rate | G4: =AVERAGE(SMALL(Q3_Validation_Base!J:J,_xlfn.FLOOR.MATH((COUNT(Q3_Validation_Base!J:J)+1)*0.25)),SMALL(Q3_Validation_Base!J:J,_xlfn.CEILING.MATH((COUNT(Q3_Validation_Base!J:J)+1)*0.25))) -> 1.0994221
F5: Raw Q3 Error Rate | G5: =AVERAGE(SMALL(Q3_Validation_Base!J:J,_xlfn.FLOOR.MATH((COUNT(Q3_Validation_Base!J:J)+1)*0.75)),SMALL(Q3_Validation_Base!J:J,_xlfn.CEILING.MATH((COUNT(Q3_Validation_Base!J:J)+1)*0.75))) -> 2.1109303
A6: Final High-error-flagged Segment Classification | B6: =COUNTA(Q3_SQL_Error_Concentration!J:J)-1 -> 391 | C6: =COUNTA(Q3_SQL_Error_Concentration!K:K)-1 -> 391 | D6: =IF(COUNTIF(Q3_SQL_Error_Concentration!L:L,"FAIL")=0,"PASS","FAIL") -> PASS | F6: IQR | G6: =G5-G4 -> 1.0115082
F7: Outlier Upper Bound | G7: =G5+1.5*G6 -> 3.6281927
A8: High-error-flagged Segment Count by MCC Helper | B8: =ROWS(_xlfn.ANCHORARRAY(F12)) -> 30 | C8: {=ROWS(_xlfn.UNIQUE(_xlfn._xlws.FILTER(Q3_Validation_Base!A2:A6050,Q3_Validation_Base!M2:M6050=1)))} -> 30 | D8: =IF(AND(B8=C8,COUNTIF(I12:I41,"FAIL")=0),"PASS","FAIL") -> PASS
A10: Total Final High-error-flagged Segment Count | B10: =COUNTA(Q3_SQL_Error_Concentration!A:A)-1 -> 391 | C10: =COUNTIF(Q3_Validation_Base!M:M,1) -> 391 | D10: =IF(B10=C10,"PASS","FAIL") -> PASS | F10: Q3-4 High-error Count by MCC Helper
F11: MCC | G11: SQL Count | H11: Excel Recalc | I11: Status
F12: {=_xlfn.UNIQUE(Q3_SQL_Error_Concentration!A2:A392)} -> 4900 | G12: =_xlfn.MAXIFS(Q3_SQL_Error_Concentration!B:B,Q3_SQL_Error_Concentration!A:A,F12) -> 50 | H12: =COUNTIFS(Q3_Validation_Base!A:A,F12,Q3_Validation_Base!K:K,"high-error")+COUNTIFS(Q3_Validation_Base!A:A,F12,Q3_Validation_Base!K:K,"outlier") -> 50 | I12: =IF(G12=H12,"PASS","FAIL") -> PASS
F13: 4814 | G13: =_xlfn.MAXIFS(Q3_SQL_Error_Concentration!B:B,Q3_SQL_Error_Concentration!A:A,F13) -> 44 | H13: =COUNTIFS(Q3_Validation_Base!A:A,F13,Q3_Validation_Base!K:K,"high-error")+COUNTIFS(Q3_Validation_Base!A:A,F13,Q3_Validation_Base!K:K,"outlier") -> 44 | I13: =IF(G13=H13,"PASS","FAIL") -> PASS
F14: 5311 | G14: =_xlfn.MAXIFS(Q3_SQL_Error_Concentration!B:B,Q3_SQL_Error_Concentration!A:A,F14) -> 33 | H14: =COUNTIFS(Q3_Validation_Base!A:A,F14,Q3_Validation_Base!K:K,"high-error")+COUNTIFS(Q3_Validation_Base!A:A,F14,Q3_Validation_Base!K:K,"outlier") -> 33 | I14: =IF(G14=H14,"PASS","FAIL") -> PASS
F15: 4829 | G15: =_xlfn.MAXIFS(Q3_SQL_Error_Concentration!B:B,Q3_SQL_Error_Concentration!A:A,F15) -> 32 | H15: =COUNTIFS(Q3_Validation_Base!A:A,F15,Q3_Validation_Base!K:K,"high-error")+COUNTIFS(Q3_Validation_Base!A:A,F15,Q3_Validation_Base!K:K,"outlier") -> 32 | I15: =IF(G15=H15,"PASS","FAIL") -> PASS
F16: 4899 | G16: =_xlfn.MAXIFS(Q3_SQL_Error_Concentration!B:B,Q3_SQL_Error_Concentration!A:A,F16) -> 24 | H16: =COUNTIFS(Q3_Validation_Base!A:A,F16,Q3_Validation_Base!K:K,"high-error")+COUNTIFS(Q3_Validation_Base!A:A,F16,Q3_Validation_Base!K:K,"outlier") -> 24 | I16: =IF(G16=H16,"PASS","FAIL") -> PASS
F17: 4111 | G17: =_xlfn.MAXIFS(Q3_SQL_Error_Concentration!B:B,Q3_SQL_Error_Concentration!A:A,F17) -> 23 | H17: =COUNTIFS(Q3_Validation_Base!A:A,F17,Q3_Validation_Base!K:K,"high-error")+COUNTIFS(Q3_Validation_Base!A:A,F17,Q3_Validation_Base!K:K,"outlier") -> 23 | I17: =IF(G17=H17,"PASS","FAIL") -> PASS
F18: 5300 | G18: =_xlfn.MAXIFS(Q3_SQL_Error_Concentration!B:B,Q3_SQL_Error_Concentration!A:A,F18) -> 20 | H18: =COUNTIFS(Q3_Validation_Base!A:A,F18,Q3_Validation_Base!K:K,"high-error")+COUNTIFS(Q3_Validation_Base!A:A,F18,Q3_Validation_Base!K:K,"outlier") -> 20 | I18: =IF(G18=H18,"PASS","FAIL") -> PASS
F19: 7922 | G19: =_xlfn.MAXIFS(Q3_SQL_Error_Concentration!B:B,Q3_SQL_Error_Concentration!A:A,F19) -> 20 | H19: =COUNTIFS(Q3_Validation_Base!A:A,F19,Q3_Validation_Base!K:K,"high-error")+COUNTIFS(Q3_Validation_Base!A:A,F19,Q3_Validation_Base!K:K,"outlier") -> 20 | I19: =IF(G19=H19,"PASS","FAIL") -> PASS
F20: 7349 | G20: =_xlfn.MAXIFS(Q3_SQL_Error_Concentration!B:B,Q3_SQL_Error_Concentration!A:A,F20) -> 19 | H20: =COUNTIFS(Q3_Validation_Base!A:A,F20,Q3_Validation_Base!K:K,"high-error")+COUNTIFS(Q3_Validation_Base!A:A,F20,Q3_Validation_Base!K:K,"outlier") -> 19 | I20: =IF(G20=H20,"PASS","FAIL") -> PASS
F21: 4722 | G21: =_xlfn.MAXIFS(Q3_SQL_Error_Concentration!B:B,Q3_SQL_Error_Concentration!A:A,F21) -> 17 | H21: =COUNTIFS(Q3_Validation_Base!A:A,F21,Q3_Validation_Base!K:K,"high-error")+COUNTIFS(Q3_Validation_Base!A:A,F21,Q3_Validation_Base!K:K,"outlier") -> 17 | I21: =IF(G21=H21,"PASS","FAIL") -> PASS
F22: 5651 | G22: =_xlfn.MAXIFS(Q3_SQL_Error_Concentration!B:B,Q3_SQL_Error_Concentration!A:A,F22) -> 17 | H22: =COUNTIFS(Q3_Validation_Base!A:A,F22,Q3_Validation_Base!K:K,"high-error")+COUNTIFS(Q3_Validation_Base!A:A,F22,Q3_Validation_Base!K:K,"outlier") -> 17 | I22: =IF(G22=H22,"PASS","FAIL") -> PASS
F23: 6300 | G23: =_xlfn.MAXIFS(Q3_SQL_Error_Concentration!B:B,Q3_SQL_Error_Concentration!A:A,F23) -> 15 | H23: =COUNTIFS(Q3_Validation_Base!A:A,F23,Q3_Validation_Base!K:K,"high-error")+COUNTIFS(Q3_Validation_Base!A:A,F23,Q3_Validation_Base!K:K,"outlier") -> 15 | I23: =IF(G23=H23,"PASS","FAIL") -> PASS
F24: 7801 | G24: =_xlfn.MAXIFS(Q3_SQL_Error_Concentration!B:B,Q3_SQL_Error_Concentration!A:A,F24) -> 10 | H24: =COUNTIFS(Q3_Validation_Base!A:A,F24,Q3_Validation_Base!K:K,"high-error")+COUNTIFS(Q3_Validation_Base!A:A,F24,Q3_Validation_Base!K:K,"outlier") -> 10 | I24: =IF(G24=H24,"PASS","FAIL") -> PASS
... F41: 8021 | G41: =_xlfn.MAXIFS(Q3_SQL_Error_Concentration!B:B,Q3_SQL_Error_Concentration!A:A,F41) -> 2 | H41: =COUNTIFS(Q3_Validation_Base!A:A,F41,Q3_Validation_Base!K:K,"high-error")+COUNTIFS(Q3_Validation_Base!A:A,F41,Q3_Validation_Base!K:K,"outlier") -> 2 | I41: =IF(G41=H41,"PASS","FAIL") -> PASS

Sheet Q4_Validation_Base
A1: mcc | B1: hour_of_day | C1: use_chip | D1: error_level | E1: card_id | F1: card_error_count
A2: 3359 | B2: 22 | C2: Swipe Transaction | D2: high-error | E2: 1195 | F2: 2
A3: 3359 | B3: 22 | C3: Swipe Transaction | D3: high-error | E3: 4570 | F3: 1
A4: 3359 | B4: 22 | C4: Swipe Transaction | D4: high-error | E4: 4976 | F4: 1
A5: 3359 | B5: 22 | C5: Swipe Transaction | D5: high-error | E5: 2048 | F5: 1
A6: 3359 | B6: 22 | C6: Swipe Transaction | D6: high-error | E6: 5099 | F6: 1
A7: 3359 | B7: 22 | C7: Swipe Transaction | D7: high-error | E7: 339 | F7: 1
A8: 3359 | B8: 22 | C8: Swipe Transaction | D8: high-error | E8: 5488 | F8: 1
A9: 3359 | B9: 22 | C9: Swipe Transaction | D9: high-error | E9: 2298 | F9: 1
A10: 3359 | B10: 22 | C10: Swipe Transaction | D10: high-error | E10: 3528 | F10: 1
A11: 3359 | B11: 22 | C11: Swipe Transaction | D11: high-error | E11: 2083 | F11: 1
A12: 3359 | B12: 22 | C12: Swipe Transaction | D12: high-error | E12: 5442 | F12: 1
A13: 3359 | B13: 22 | C13: Swipe Transaction | D13: high-error | E13: 5050 | F13: 1
... A21859: 8043 | B21859: 16 | C21859: Swipe Transaction | D21859: high-error | E21859: 4083 | F21859: 1

Sheet Q4_SQL_Error_Card_Repetition
A1: mcc | B1: high_error_segment_count | C1: outlier_segment_count | D1: mcc_avg_eligible_segment_error_rate_pct | E1: hour_of_day | F1: use_chip | G1: transaction_count | H1: error_transaction_count | I1: error_rate_pct | J1: error_level | K1: error_card_count | L1: single_error_card_count | M1: repeat_error_card_count | N1: avg_errors_per_error_card | O1: repeat_error_card_share_pct | P1: max_card_error_count | Q1: top_card_error_share_pct | R1: card_repetition_level
A2: 7538 | B2: 5 | C2: 2 | D2: 1.6956 | E2: 4 | F2: Swipe Transaction | G2: 3024 | H2: 140 | I2: 4.6296 | J2: outlier | K2: 9 | L2: 4 | M2: 5 | N2: 15.5556 | O2: 55.5556 | P2: 113 | Q2: 80.7143 | R2: repeat-concentrated
A3: 4829 | B3: 32 | C3: 11 | D3: 2.9543 | E3: 7 | F3: Chip Transaction | G3: 14998 | H3: 1464 | I3: 9.7613 | J3: outlier | K3: 103 | L3: 55 | M3: 48 | N3: 14.2136 | O3: 46.6019 | P3: 395 | Q3: 26.9809 | R3: repeat-concentrated
A4: 4111 | B4: 23 | C4: 8 | D4: 2.994 | E4: 21 | F4: Swipe Transaction | G4: 2543 | H4: 63 | I4: 2.4774 | J4: high-error | K4: 5 | L4: 1 | M4: 4 | N4: 12.6 | O4: 80 | P4: 27 | Q4: 42.8571 | R4: repeat-concentrated
A5: 4829 | B5: 32 | C5: 11 | D5: 2.9543 | E5: 7 | F5: Swipe Transaction | G5: 19550 | H5: 1687 | I5: 8.6292 | J5: outlier | K5: 137 | L5: 65 | M5: 72 | N5: 12.3139 | O5: 52.5547 | P5: 424 | Q5: 25.1334 | R5: repeat-concentrated
A6: 4829 | B6: 32 | C6: 11 | D6: 2.9543 | E6: 4 | F6: Chip Transaction | G6: 635 | H6: 47 | I6: 7.4016 | J6: outlier | K6: 4 | L6: 1 | M6: 3 | N6: 11.75 | O6: 75 | P6: 33 | Q6: 70.2128 | R6: repeat-concentrated
A7: 4784 | B7: 6 | C7: 0 | D7: 2.0461 | E7: 2 | F7: Online Transaction | G7: 5900 | H7: 140 | I7: 2.3729 | J7: high-error | K7: 12 | L7: 3 | M7: 9 | N7: 11.6667 | O7: 75 | P7: 56 | Q7: 40 | R7: repeat-concentrated
A8: 4784 | B8: 6 | C8: 0 | D8: 2.0461 | E8: 19 | F8: Online Transaction | G8: 23894 | H8: 573 | I8: 2.3981 | J8: high-error | K8: 52 | L8: 6 | M8: 46 | N8: 11.0192 | O8: 88.4615 | P8: 77 | Q8: 13.4381 | R8: repeat-concentrated
A9: 4784 | B9: 6 | C9: 0 | D9: 2.0461 | E9: 4 | F9: Online Transaction | G9: 6584 | H9: 142 | I9: 2.1567 | J9: high-error | K9: 13 | L9: 7 | M9: 6 | N9: 10.9231 | O9: 46.1539 | P9: 58 | Q9: 40.8451 | R9: repeat-concentrated
A10: 4111 | B10: 23 | C10: 8 | D10: 2.994 | E10: 21 | F10: Chip Transaction | G10: 2316 | H10: 62 | I10: 2.677 | J10: high-error | K10: 6 | L10: 2 | M10: 4 | N10: 10.3333 | O10: 66.6667 | P10: 30 | Q10: 48.3871 | R10: repeat-concentrated
A11: 4829 | B11: 32 | C11: 11 | D11: 2.9543 | E11: 20 | F11: Swipe Transaction | G11: 14978 | H11: 607 | I11: 4.0526 | J11: outlier | K11: 79 | L11: 34 | M11: 45 | N11: 7.6835 | O11: 56.962 | P11: 167 | Q11: 27.5124 | R11: repeat-concentrated
A12: 4111 | B12: 23 | C12: 8 | D12: 2.994 | E12: 10 | F12: Chip Transaction | G12: 4034 | H12: 167 | I12: 4.1398 | J12: outlier | K12: 22 | L12: 5 | M12: 17 | N12: 7.5909 | O12: 77.2727 | P12: 35 | Q12: 20.9581 | R12: repeat-concentrated
A13: 4829 | B13: 32 | C13: 11 | D13: 2.9543 | E13: 19 | F13: Chip Transaction | G13: 8352 | H13: 416 | I13: 4.9808 | J13: outlier | K13: 55 | L13: 28 | M13: 27 | N13: 7.5636 | O13: 49.0909 | P13: 142 | Q13: 34.1346 | R13: repeat-concentrated
... A392: 4722 | B392: 17 | C392: 0 | D392: 2.9914 | E392: 15 | F392: Online Transaction | G392: 1356 | H392: 38 | I392: 2.8024 | J392: high-error | K392: 38 | L392: 38 | M392: 0 | N392: 1 | O392: 0 | P392: 1 | Q392: 2.6316 | R392: low-repeat

Sheet Q4_Validation
A1: KPI | B1: SQL Value | C1: Excel Recalc | D1: Status | F1: Q4 Helper | AC1: Card Repetition Level Distribution
A2: Total Error Card Count across Flagged Segments | B2: =SUM(Q4_SQL_Error_Card_Repetition!K2:K392) -> 21858 | C2: =SUM(J3:J393) -> 21858 | D2: =IF(AND(B2=C2,COUNTIF(K3:K393,"FAIL")=0),"PASS","FAIL") -> PASS | F2: MCC | G2: Hour | H2: Use Chip | I2: SQL Error Card Count | J2: Excel Recalc | K2: Status | L2: SQL Repeat Error Card Count | M2: Excel Recalc | N2: Status | O2: SQL Avg Errors per Error Card | P2: Excel Recalc | Q2: Status | R2: SQL Repeat Error Card Share (%) | S2: Excel Recalc | T2: Status | U2: SQL Top Card Error Share (%) | V2: Excel Recalc | W2: Status | X2: SQL Card Repetition Level | Y2: Excel Recalc | Z2: Status | AC2: Repetition Level | AD2: SQL Count | AE2: Excel Recalc | AF2: SQL Share (%) | AG2: Excel Share (%) | AH2: Status
F3: =Q4_SQL_Error_Card_Repetition!A2 -> 7538 | G3: =Q4_SQL_Error_Card_Repetition!E2 -> 4 | H3: =Q4_SQL_Error_Card_Repetition!F2 -> Swipe Transaction | I3: =Q4_SQL_Error_Card_Repetition!K2 -> 9 | J3: =COUNTIFS(Q4_Validation_Base!A:A,F3,Q4_Validation_Base!B:B,G3,Q4_Validation_Base!C:C,H3) -> 9 | K3: =IF(I3=J3,"PASS","FAIL") -> PASS | L3: =Q4_SQL_Error_Card_Repetition!M2 -> 5 | M3: =COUNTIFS(Q4_Validation_Base!A:A,F3,Q4_Validation_Base!B:B,G3,Q4_Validation_Base!C:C,H3,Q4_Validation_Base!F:F,">=2") -> 5 | N3: =IF(L3=M3,"PASS","FAIL") -> PASS | O3: =Q4_SQL_Error_Card_Repetition!N2 -> 15.5556 | P3: =SUMIFS(Q4_Validation_Base!F:F,Q4_Validation_Base!A:A,F3,Q4_Validation_Base!B:B,G3,Q4_Validation_Base!C:C,H3)/J3 -> 15.555556 | Q3: =IF(ROUND(O3,4)=ROUND(P3,4),"PASS","FAIL") -> PASS | R3: =Q4_SQL_Error_Card_Repetition!O2 -> 55.5556 | S3: =M3/J3*100 -> 55.555556 | T3: =IF(ABS(R3-S3)<=0.0002,"PASS","FAIL") -> PASS | U3: =Q4_SQL_Error_Card_Repetition!Q2 -> 80.7143 | V3: =_xlfn.MAXIFS(Q4_Validation_Base!F:F,Q4_Validation_Base!A:A,F3,Q4_Validation_Base!B:B,G3,Q4_Validation_Base!C:C,H3)/SUMIFS(Q4_Validation_Base!F:F,Q4_Validation_Base!A:A,F3,Q4_Validation_Base!B:B,G3,Q4_Validation_Base!C:C,H3)*100 -> 80.714286 | W3: =IF(ABS(U3-V3)<=0.0001,"PASS","FAIL") -> PASS | X3: =Q4_SQL_Error_Card_Repetition!R2 -> repeat-concentrated | Y3: =IF(P3<1.5,"low-repeat",IF(P3<2,"mixed","repeat-concentrated")) -> repeat-concentrated | Z3: =IF(X3=Y3,"PASS","FAIL") -> PASS | AC3: low-repeat | AD3: =COUNTIF(Q4_SQL_Error_Card_Repetition!R:R,AC3) -> 225 | AE3: =COUNTIF($Y$3:$Y$393,AC3) -> 225 | AF3: =AD3/SUM($AD$3:$AD$5)*100 -> 57.544757 | AG3: =AE3/SUM($AE$3:$AE$5)*100 -> 57.544757 | AH3: =IF(AND(AD3=AE3,ABS(AF3-AG3)<=0.01),"PASS","FAIL") -> PASS
A4: Total Repeat Error Card Count across Flagged Segments | B4: =SUM(Q4_SQL_Error_Card_Repetition!M2:M392) -> 6559 | C4: =SUM(M3:M393) -> 6559 | D4: =IF(AND(B4=C4,COUNTIF(N3:N393,"FAIL")=0),"PASS","FAIL") -> PASS | F4: =Q4_SQL_Error_Card_Repetition!A3 -> 4829 | G4: =Q4_SQL_Error_Card_Repetition!E3 -> 7 | H4: =Q4_SQL_Error_Card_Repetition!F3 -> Chip Transaction | I4: =Q4_SQL_Error_Card_Repetition!K3 -> 103 | J4: =COUNTIFS(Q4_Validation_Base!A:A,F4,Q4_Validation_Base!B:B,G4,Q4_Validation_Base!C:C,H4) -> 103 | K4: =IF(I4=J4,"PASS","FAIL") -> PASS | L4: =Q4_SQL_Error_Card_Repetition!M3 -> 48 | M4: =COUNTIFS(Q4_Validation_Base!A:A,F4,Q4_Validation_Base!B:B,G4,Q4_Validation_Base!C:C,H4,Q4_Validation_Base!F:F,">=2") -> 48 | N4: =IF(L4=M4,"PASS","FAIL") -> PASS | O4: =Q4_SQL_Error_Card_Repetition!N3 -> 14.2136 | P4: =SUMIFS(Q4_Validation_Base!F:F,Q4_Validation_Base!A:A,F4,Q4_Validation_Base!B:B,G4,Q4_Validation_Base!C:C,H4)/J4 -> 14.213592 | Q4: =IF(ROUND(O4,4)=ROUND(P4,4),"PASS","FAIL") -> PASS | R4: =Q4_SQL_Error_Card_Repetition!O3 -> 46.6019 | S4: =M4/J4*100 -> 46.601942 | T4: =IF(ABS(R4-S4)<=0.0002,"PASS","FAIL") -> PASS | U4: =Q4_SQL_Error_Card_Repetition!Q3 -> 26.9809 | V4: =_xlfn.MAXIFS(Q4_Validation_Base!F:F,Q4_Validation_Base!A:A,F4,Q4_Validation_Base!B:B,G4,Q4_Validation_Base!C:C,H4)/SUMIFS(Q4_Validation_Base!F:F,Q4_Validation_Base!A:A,F4,Q4_Validation_Base!B:B,G4,Q4_Validation_Base!C:C,H4)*100 -> 26.980874 | W4: =IF(ABS(U4-V4)<=0.0001,"PASS","FAIL") -> PASS | X4: =Q4_SQL_Error_Card_Repetition!R3 -> repeat-concentrated | Y4: =IF(P4<1.5,"low-repeat",IF(P4<2,"mixed","repeat-concentrated")) -> repeat-concentrated | Z4: =IF(X4=Y4,"PASS","FAIL") -> PASS | AC4: mixed | AD4: =COUNTIF(Q4_SQL_Error_Card_Repetition!R:R,AC4) -> 66 | AE4: =COUNTIF($Y$3:$Y$393,AC4) -> 66 | AF4: =AD4/SUM($AD$3:$AD$5)*100 -> 16.879795 | AG4: =AE4/SUM($AE$3:$AE$5)*100 -> 16.879795 | AH4: =IF(AND(AD4=AE4,ABS(AF4-AG4)<=0.01),"PASS","FAIL") -> PASS
F5: =Q4_SQL_Error_Card_Repetition!A4 -> 4111 | G5: =Q4_SQL_Error_Card_Repetition!E4 -> 21 | H5: =Q4_SQL_Error_Card_Repetition!F4 -> Swipe Transaction | I5: =Q4_SQL_Error_Card_Repetition!K4 -> 5 | J5: =COUNTIFS(Q4_Validation_Base!A:A,F5,Q4_Validation_Base!B:B,G5,Q4_Validation_Base!C:C,H5) -> 5 | K5: =IF(I5=J5,"PASS","FAIL") -> PASS | L5: =Q4_SQL_Error_Card_Repetition!M4 -> 4 | M5: =COUNTIFS(Q4_Validation_Base!A:A,F5,Q4_Validation_Base!B:B,G5,Q4_Validation_Base!C:C,H5,Q4_Validation_Base!F:F,">=2") -> 4 | N5: =IF(L5=M5,"PASS","FAIL") -> PASS | O5: =Q4_SQL_Error_Card_Repetition!N4 -> 12.6 | P5: =SUMIFS(Q4_Validation_Base!F:F,Q4_Validation_Base!A:A,F5,Q4_Validation_Base!B:B,G5,Q4_Validation_Base!C:C,H5)/J5 -> 12.6 | Q5: =IF(ROUND(O5,4)=ROUND(P5,4),"PASS","FAIL") -> PASS | R5: =Q4_SQL_Error_Card_Repetition!O4 -> 80 | S5: =M5/J5*100 -> 80 | T5: =IF(ABS(R5-S5)<=0.0002,"PASS","FAIL") -> PASS | U5: =Q4_SQL_Error_Card_Repetition!Q4 -> 42.8571 | V5: =_xlfn.MAXIFS(Q4_Validation_Base!F:F,Q4_Validation_Base!A:A,F5,Q4_Validation_Base!B:B,G5,Q4_Validation_Base!C:C,H5)/SUMIFS(Q4_Validation_Base!F:F,Q4_Validation_Base!A:A,F5,Q4_Validation_Base!B:B,G5,Q4_Validation_Base!C:C,H5)*100 -> 42.857143 | W5: =IF(ABS(U5-V5)<=0.0001,"PASS","FAIL") -> PASS | X5: =Q4_SQL_Error_Card_Repetition!R4 -> repeat-concentrated | Y5: =IF(P5<1.5,"low-repeat",IF(P5<2,"mixed","repeat-concentrated")) -> repeat-concentrated | Z5: =IF(X5=Y5,"PASS","FAIL") -> PASS | AC5: repeat-concentrated | AD5: =COUNTIF(Q4_SQL_Error_Card_Repetition!R:R,AC5) -> 100 | AE5: =COUNTIF($Y$3:$Y$393,AC5) -> 100 | AF5: =AD5/SUM($AD$3:$AD$5)*100 -> 25.575448 | AG5: =AE5/SUM($AE$3:$AE$5)*100 -> 25.575448 | AH5: =IF(AND(AD5=AE5,ABS(AF5-AG5)<=0.01),"PASS","FAIL") -> PASS
A6: Average Errors per Error Card across Segments | B6: =AVERAGE(Q4_SQL_Error_Card_Repetition!N2:N392) -> 2.2092302 | C6: =AVERAGE(P3:P393) -> 2.2092292 | D6: =IF(AND(ABS(B6-C6)<=0.0001,COUNTIF(Q3:Q393,"FAIL")=0),"PASS","FAIL") -> PASS | F6: =Q4_SQL_Error_Card_Repetition!A5 -> 4829 | G6: =Q4_SQL_Error_Card_Repetition!E5 -> 7 | H6: =Q4_SQL_Error_Card_Repetition!F5 -> Swipe Transaction | I6: =Q4_SQL_Error_Card_Repetition!K5 -> 137 | J6: =COUNTIFS(Q4_Validation_Base!A:A,F6,Q4_Validation_Base!B:B,G6,Q4_Validation_Base!C:C,H6) -> 137 | K6: =IF(I6=J6,"PASS","FAIL") -> PASS | L6: =Q4_SQL_Error_Card_Repetition!M5 -> 72 | M6: =COUNTIFS(Q4_Validation_Base!A:A,F6,Q4_Validation_Base!B:B,G6,Q4_Validation_Base!C:C,H6,Q4_Validation_Base!F:F,">=2") -> 72 | N6: =IF(L6=M6,"PASS","FAIL") -> PASS | O6: =Q4_SQL_Error_Card_Repetition!N5 -> 12.3139 | P6: =SUMIFS(Q4_Validation_Base!F:F,Q4_Validation_Base!A:A,F6,Q4_Validation_Base!B:B,G6,Q4_Validation_Base!C:C,H6)/J6 -> 12.313869 | Q6: =IF(ROUND(O6,4)=ROUND(P6,4),"PASS","FAIL") -> PASS | R6: =Q4_SQL_Error_Card_Repetition!O5 -> 52.5547 | S6: =M6/J6*100 -> 52.554745 | T6: =IF(ABS(R6-S6)<=0.0002,"PASS","FAIL") -> PASS | U6: =Q4_SQL_Error_Card_Repetition!Q5 -> 25.1334 | V6: =_xlfn.MAXIFS(Q4_Validation_Base!F:F,Q4_Validation_Base!A:A,F6,Q4_Validation_Base!B:B,G6,Q4_Validation_Base!C:C,H6)/SUMIFS(Q4_Validation_Base!F:F,Q4_Validation_Base!A:A,F6,Q4_Validation_Base!B:B,G6,Q4_Validation_Base!C:C,H6)*100 -> 25.133373 | W6: =IF(ABS(U6-V6)<=0.0001,"PASS","FAIL") -> PASS | X6: =Q4_SQL_Error_Card_Repetition!R5 -> repeat-concentrated | Y6: =IF(P6<1.5,"low-repeat",IF(P6<2,"mixed","repeat-concentrated")) -> repeat-concentrated | Z6: =IF(X6=Y6,"PASS","FAIL") -> PASS
F7: =Q4_SQL_Error_Card_Repetition!A6 -> 4829 | G7: =Q4_SQL_Error_Card_Repetition!E6 -> 4 | H7: =Q4_SQL_Error_Card_Repetition!F6 -> Chip Transaction | I7: =Q4_SQL_Error_Card_Repetition!K6 -> 4 | J7: =COUNTIFS(Q4_Validation_Base!A:A,F7,Q4_Validation_Base!B:B,G7,Q4_Validation_Base!C:C,H7) -> 4 | K7: =IF(I7=J7,"PASS","FAIL") -> PASS | L7: =Q4_SQL_Error_Card_Repetition!M6 -> 3 | M7: =COUNTIFS(Q4_Validation_Base!A:A,F7,Q4_Validation_Base!B:B,G7,Q4_Validation_Base!C:C,H7,Q4_Validation_Base!F:F,">=2") -> 3 | N7: =IF(L7=M7,"PASS","FAIL") -> PASS | O7: =Q4_SQL_Error_Card_Repetition!N6 -> 11.75 | P7: =SUMIFS(Q4_Validation_Base!F:F,Q4_Validation_Base!A:A,F7,Q4_Validation_Base!B:B,G7,Q4_Validation_Base!C:C,H7)/J7 -> 11.75 | Q7: =IF(ROUND(O7,4)=ROUND(P7,4),"PASS","FAIL") -> PASS | R7: =Q4_SQL_Error_Card_Repetition!O6 -> 75 | S7: =M7/J7*100 -> 75 | T7: =IF(ABS(R7-S7)<=0.0002,"PASS","FAIL") -> PASS | U7: =Q4_SQL_Error_Card_Repetition!Q6 -> 70.2128 | V7: =_xlfn.MAXIFS(Q4_Validation_Base!F:F,Q4_Validation_Base!A:A,F7,Q4_Validation_Base!B:B,G7,Q4_Validation_Base!C:C,H7)/SUMIFS(Q4_Validation_Base!F:F,Q4_Validation_Base!A:A,F7,Q4_Validation_Base!B:B,G7,Q4_Validation_Base!C:C,H7)*100 -> 70.212766 | W7: =IF(ABS(U7-V7)<=0.0001,"PASS","FAIL") -> PASS | X7: =Q4_SQL_Error_Card_Repetition!R6 -> repeat-concentrated | Y7: =IF(P7<1.5,"low-repeat",IF(P7<2,"mixed","repeat-concentrated")) -> repeat-concentrated | Z7: =IF(X7=Y7,"PASS","FAIL") -> PASS
A8: Average Repeat Error Card Share (%) across Segments | B8: =AVERAGE(Q4_SQL_Error_Card_Repetition!O2:O392) -> 28.698197 | C8: =AVERAGE(S3:S393) -> 28.698196 | D8: =IF(AND(ABS(B8-C8)<=0.0001,COUNTIF(T3:T393,"FAIL")=0),"PASS","FAIL") -> PASS | F8: =Q4_SQL_Error_Card_Repetition!A7 -> 4784 | G8: =Q4_SQL_Error_Card_Repetition!E7 -> 2 | H8: =Q4_SQL_Error_Card_Repetition!F7 -> Online Transaction | I8: =Q4_SQL_Error_Card_Repetition!K7 -> 12 | J8: =COUNTIFS(Q4_Validation_Base!A:A,F8,Q4_Validation_Base!B:B,G8,Q4_Validation_Base!C:C,H8) -> 12 | K8: =IF(I8=J8,"PASS","FAIL") -> PASS | L8: =Q4_SQL_Error_Card_Repetition!M7 -> 9 | M8: =COUNTIFS(Q4_Validation_Base!A:A,F8,Q4_Validation_Base!B:B,G8,Q4_Validation_Base!C:C,H8,Q4_Validation_Base!F:F,">=2") -> 9 | N8: =IF(L8=M8,"PASS","FAIL") -> PASS | O8: =Q4_SQL_Error_Card_Repetition!N7 -> 11.6667 | P8: =SUMIFS(Q4_Validation_Base!F:F,Q4_Validation_Base!A:A,F8,Q4_Validation_Base!B:B,G8,Q4_Validation_Base!C:C,H8)/J8 -> 11.666667 | Q8: =IF(ROUND(O8,4)=ROUND(P8,4),"PASS","FAIL") -> PASS | R8: =Q4_SQL_Error_Card_Repetition!O7 -> 75 | S8: =M8/J8*100 -> 75 | T8: =IF(ABS(R8-S8)<=0.0002,"PASS","FAIL") -> PASS | U8: =Q4_SQL_Error_Card_Repetition!Q7 -> 40 | V8: =_xlfn.MAXIFS(Q4_Validation_Base!F:F,Q4_Validation_Base!A:A,F8,Q4_Validation_Base!B:B,G8,Q4_Validation_Base!C:C,H8)/SUMIFS(Q4_Validation_Base!F:F,Q4_Validation_Base!A:A,F8,Q4_Validation_Base!B:B,G8,Q4_Validation_Base!C:C,H8)*100 -> 40 | W8: =IF(ABS(U8-V8)<=0.0001,"PASS","FAIL") -> PASS | X8: =Q4_SQL_Error_Card_Repetition!R7 -> repeat-concentrated | Y8: =IF(P8<1.5,"low-repeat",IF(P8<2,"mixed","repeat-concentrated")) -> repeat-concentrated | Z8: =IF(X8=Y8,"PASS","FAIL") -> PASS
F9: =Q4_SQL_Error_Card_Repetition!A8 -> 4784 | G9: =Q4_SQL_Error_Card_Repetition!E8 -> 19 | H9: =Q4_SQL_Error_Card_Repetition!F8 -> Online Transaction | I9: =Q4_SQL_Error_Card_Repetition!K8 -> 52 | J9: =COUNTIFS(Q4_Validation_Base!A:A,F9,Q4_Validation_Base!B:B,G9,Q4_Validation_Base!C:C,H9) -> 52 | K9: =IF(I9=J9,"PASS","FAIL") -> PASS | L9: =Q4_SQL_Error_Card_Repetition!M8 -> 46 | M9: =COUNTIFS(Q4_Validation_Base!A:A,F9,Q4_Validation_Base!B:B,G9,Q4_Validation_Base!C:C,H9,Q4_Validation_Base!F:F,">=2") -> 46 | N9: =IF(L9=M9,"PASS","FAIL") -> PASS | O9: =Q4_SQL_Error_Card_Repetition!N8 -> 11.0192 | P9: =SUMIFS(Q4_Validation_Base!F:F,Q4_Validation_Base!A:A,F9,Q4_Validation_Base!B:B,G9,Q4_Validation_Base!C:C,H9)/J9 -> 11.019231 | Q9: =IF(ROUND(O9,4)=ROUND(P9,4),"PASS","FAIL") -> PASS | R9: =Q4_SQL_Error_Card_Repetition!O8 -> 88.4615 | S9: =M9/J9*100 -> 88.461538 | T9: =IF(ABS(R9-S9)<=0.0002,"PASS","FAIL") -> PASS | U9: =Q4_SQL_Error_Card_Repetition!Q8 -> 13.4381 | V9: =_xlfn.MAXIFS(Q4_Validation_Base!F:F,Q4_Validation_Base!A:A,F9,Q4_Validation_Base!B:B,G9,Q4_Validation_Base!C:C,H9)/SUMIFS(Q4_Validation_Base!F:F,Q4_Validation_Base!A:A,F9,Q4_Validation_Base!B:B,G9,Q4_Validation_Base!C:C,H9)*100 -> 13.438045 | W9: =IF(ABS(U9-V9)<=0.0001,"PASS","FAIL") -> PASS | X9: =Q4_SQL_Error_Card_Repetition!R8 -> repeat-concentrated | Y9: =IF(P9<1.5,"low-repeat",IF(P9<2,"mixed","repeat-concentrated")) -> repeat-concentrated | Z9: =IF(X9=Y9,"PASS","FAIL") -> PASS
A10: Average Top Card Error Share (%) across Segments | B10: =AVERAGE(Q4_SQL_Error_Card_Repetition!Q2:Q392) -> 13.071931 | C10: =AVERAGE(V3:V393) -> 13.071928 | D10: =IF(AND(ABS(B10-C10)<=0.0001,COUNTIF(W3:W393,"FAIL")=0),"PASS","FAIL") -> PASS | F10: =Q4_SQL_Error_Card_Repetition!A9 -> 4784 | G10: =Q4_SQL_Error_Card_Repetition!E9 -> 4 | H10: =Q4_SQL_Error_Card_Repetition!F9 -> Online Transaction | I10: =Q4_SQL_Error_Card_Repetition!K9 -> 13 | J10: =COUNTIFS(Q4_Validation_Base!A:A,F10,Q4_Validation_Base!B:B,G10,Q4_Validation_Base!C:C,H10) -> 13 | K10: =IF(I10=J10,"PASS","FAIL") -> PASS | L10: =Q4_SQL_Error_Card_Repetition!M9 -> 6 | M10: =COUNTIFS(Q4_Validation_Base!A:A,F10,Q4_Validation_Base!B:B,G10,Q4_Validation_Base!C:C,H10,Q4_Validation_Base!F:F,">=2") -> 6 | N10: =IF(L10=M10,"PASS","FAIL") -> PASS | O10: =Q4_SQL_Error_Card_Repetition!N9 -> 10.9231 | P10: =SUMIFS(Q4_Validation_Base!F:F,Q4_Validation_Base!A:A,F10,Q4_Validation_Base!B:B,G10,Q4_Validation_Base!C:C,H10)/J10 -> 10.923077 | Q10: =IF(ROUND(O10,4)=ROUND(P10,4),"PASS","FAIL") -> PASS | R10: =Q4_SQL_Error_Card_Repetition!O9 -> 46.1539 | S10: =M10/J10*100 -> 46.153846 | T10: =IF(ABS(R10-S10)<=0.0002,"PASS","FAIL") -> PASS | U10: =Q4_SQL_Error_Card_Repetition!Q9 -> 40.8451 | V10: =_xlfn.MAXIFS(Q4_Validation_Base!F:F,Q4_Validation_Base!A:A,F10,Q4_Validation_Base!B:B,G10,Q4_Validation_Base!C:C,H10)/SUMIFS(Q4_Validation_Base!F:F,Q4_Validation_Base!A:A,F10,Q4_Validation_Base!B:B,G10,Q4_Validation_Base!C:C,H10)*100 -> 40.84507 | W10: =IF(ABS(U10-V10)<=0.0001,"PASS","FAIL") -> PASS | X10: =Q4_SQL_Error_Card_Repetition!R9 -> repeat-concentrated | Y10: =IF(P10<1.5,"low-repeat",IF(P10<2,"mixed","repeat-concentrated")) -> repeat-concentrated | Z10: =IF(X10=Y10,"PASS","FAIL") -> PASS
F11: =Q4_SQL_Error_Card_Repetition!A10 -> 4111 | G11: =Q4_SQL_Error_Card_Repetition!E10 -> 21 | H11: =Q4_SQL_Error_Card_Repetition!F10 -> Chip Transaction | I11: =Q4_SQL_Error_Card_Repetition!K10 -> 6 | J11: =COUNTIFS(Q4_Validation_Base!A:A,F11,Q4_Validation_Base!B:B,G11,Q4_Validation_Base!C:C,H11) -> 6 | K11: =IF(I11=J11,"PASS","FAIL") -> PASS | L11: =Q4_SQL_Error_Card_Repetition!M10 -> 4 | M11: =COUNTIFS(Q4_Validation_Base!A:A,F11,Q4_Validation_Base!B:B,G11,Q4_Validation_Base!C:C,H11,Q4_Validation_Base!F:F,">=2") -> 4 | N11: =IF(L11=M11,"PASS","FAIL") -> PASS | O11: =Q4_SQL_Error_Card_Repetition!N10 -> 10.3333 | P11: =SUMIFS(Q4_Validation_Base!F:F,Q4_Validation_Base!A:A,F11,Q4_Validation_Base!B:B,G11,Q4_Validation_Base!C:C,H11)/J11 -> 10.333333 | Q11: =IF(ROUND(O11,4)=ROUND(P11,4),"PASS","FAIL") -> PASS | R11: =Q4_SQL_Error_Card_Repetition!O10 -> 66.6667 | S11: =M11/J11*100 -> 66.666667 | T11: =IF(ABS(R11-S11)<=0.0002,"PASS","FAIL") -> PASS | U11: =Q4_SQL_Error_Card_Repetition!Q10 -> 48.3871 | V11: =_xlfn.MAXIFS(Q4_Validation_Base!F:F,Q4_Validation_Base!A:A,F11,Q4_Validation_Base!B:B,G11,Q4_Validation_Base!C:C,H11)/SUMIFS(Q4_Validation_Base!F:F,Q4_Validation_Base!A:A,F11,Q4_Validation_Base!B:B,G11,Q4_Validation_Base!C:C,H11)*100 -> 48.387097 | W11: =IF(ABS(U11-V11)<=0.0001,"PASS","FAIL") -> PASS | X11: =Q4_SQL_Error_Card_Repetition!R10 -> repeat-concentrated | Y11: =IF(P11<1.5,"low-repeat",IF(P11<2,"mixed","repeat-concentrated")) -> repeat-concentrated | Z11: =IF(X11=Y11,"PASS","FAIL") -> PASS
